Workbook
Name _Hlk219322800: Szoftver!$B$12

Sheet Alapadatok
B2: A pályázó rendelkezik DII felméréssel? | I2: TRUE | K2: Bemeneti mérés igazolása:
B3: Ha igen, át kell vezetni (lentre), a megszerzés időpontja:
B4: Ha igen, a pályázónak a DKF oldalon végzett digitális szintfelmérésekor kapott DI pontszáma. A lenti táblázatban pipáld be a relevánsakat! | H4: =H46 -> 2 | K4: A kiindulási digitális intenzitási szint megállapítását és ezzel a támogatásra való jogosultság igazolásaként kizárólag a fenti rendszerből származó, egyedi azonosítóval ellátott, érvényes bemeneti felmérés eredményét igazoló „Igazolás a vállalati digitális intenzitási szint pontszámról és szintről” nevű dokumentum fogadható el.
B6: A pályamű benyújtásakor meglévő digitális intenzitási szint: | H6: =Költségvetés!K34 -> Nagyon alacsony intenzitás, pályázhat
B7: A projekt megvalósításával vállalt digitális intenzitási szint: | H7: =Költségvetés!K37 -> Alacsony intenzitás | K7: A bemeneti felmérés keretében kitöltésre kerülő kérdőív eredményeképpen szintén kiállításra kerül a fenti rendszerben egy egyedi azonosítóval ellátott, érvényes, a bemeneti felmérés eredménye alapján megállapított „Igazolás a vállalati Közösségi mutató alapján meghatározott digitális intenzitási pontszámról és szintről” nevű, a közösségi mutató szerinti digitális intenzitási szint bemeneti mérését igazoló dokumentum is, amely csatolása a támogatási kérelemhez szintén szükséges.
B8: Szintugrás mértéke, tervezetten: | H8: =Költségvetés!K41 -> A fejlesztések bevezetésével a pályázó 1 szintet ugrik
B10: A pályázó már rendelkezik a DFK -val? | I10: FALSE
B11: Ha igen, mikor szerezte meg?
B12: Ha nem, a pályázó vállalja a DFK minősítés megszerzését? | I12: TRUE | K12: A fenti igazolások eredeti, hitelesített változatát a támogatási kérelemhez be kell nyújtani. A felmérés elvégzésének időpontja nem lehet korábbi, mint a támogatási kérelem benyújtását megelőző 60 nap.
B14: A pályázónál figyelembe vehető alkalmazotti / alvállalkozói létszám: | H14: 3
B16: Tervezett projekt időtartam, hónapban kifejezve: | H16: 12
B20: DII kérdőív a bemeneti méréshez, intenzitás meghatározáshoz (az adatokat a későbbiekben automatikusan felhasználjuk)
B22: Legalább 30 Mbps sebességű helyhez kötött internetkapcsolat | I22: TRUE
B23: Alkalmazottak több mint 50%-a rendelkezik internet-hozzáféréssel üzleti célból | I23: FALSE
B24: Távoli hozzáférés a következők valamelyikéhez: e-mail, dokumentumok, üzleti alkalmazás | I24: TRUE
B25: Online (távoli) megbeszélések tartása | I25: FALSE
B26: IKT-képzés biztosítása az alkalmazottaknak | I26: FALSE
B27: IKT-szakember igénybevétele | I27: FALSE
B28: Alkalmazottak tájékoztatása az IKT-biztonsággal kapcsolatos kötelezettségeikről | I28: FALSE
B29: Legalább 3 IKT-biztonsági intézkedés alkalmazása | I29: FALSE
B30: IKT-biztonsági gyakorlatokat, eljárásokat rögzítő dokumentumok megléte | I30: FALSE
B31: Saját weboldallal/honlappal való rendelkezés | I31: FALSE
B32: Bármilyen közösségi média használata | I32: FALSE
B33: Kettő vagy több típusú közösségi média használata | I33: FALSE
... B44: Elektronikus (weblap/applikáció/EDI) értékesítés | I44: FALSE
B46: Összesen: | H46: =COUNTIFS(I22:I44,TRUE) -> 2

Sheet Hardver
B2: Eszköztípus | C2: Mértékegység | D2: Mennyiség | E2: Egységköltség NETTÓ elszámoló, (Ft) | F2: Egységköltség BRUTTÓ elszámoló (Ft) | G2: Összköltség NETTÓ (Ft) | H2: Minimális műszaki jellemzők | I2: Alátámasztó dokumentumok
B3: Számítógép | C3: db | D3: 1 | E3: 388600 | F3: 493522 | G3: =E3*D3 -> 388600 | H3: Intel - i7/AMD - Ryzen 7/Apple - M2 Pro / M3/Qualcomm - Snapdragon X Elite,512GB SSD, 16 GB RAM | I3: Eszköznyilvántartási lap és alátámasztó dokumentumok - Üzembe helyezési okmány (pl. jegyzőkönyv), vagy - Üzembe helyezési okmány hiányában szállítólevél vagy átadás-átvételi jegyzőkönyv vagy állományba vételi bizonylat, vagy - Webáruházból történő vásárlás esetén üzembe helyezési jegyzőkönyv vagy állományba vételi bizonylat)
B4: Monitor | C4: db | D4: 1 | E4: 62300 | F4: 79121 | G4: =E4*D4 -> 62300 | H4: QHD_2560*1440, 27" | I4: Eszköznyilvántartási lap és alátámasztó dokumentumok - Üzembe helyezési okmány (pl. jegyzőkönyv), vagy - Üzembe helyezési okmány hiányában szállítólevél vagy átadás-átvételi jegyzőkönyv vagy állományba vételi bizonylat, vagy - Webáruházból történő vásárlás esetén üzembe helyezési jegyzőkönyv vagy állományba vételi bizonylat)
B5: Laptop | C5: db | D5: 1 | E5: 338300 | F5: 429641 | G5: =E5*D5 -> 338300 | H5: képernyő 14”, Intel - i7/AMD - Ryzen 7/Apple - M2 Pro / M3/Qualcomm - Snapdragon X Elite, 512GB SSD, 16GB | I5: Eszköznyilvántartási lap és alátámasztó dokumentumok - Üzembe helyezési okmány (pl. jegyzőkönyv), vagy - Üzembe helyezési okmány hiányában szállítólevél vagy átadás-átvételi jegyzőkönyv vagy állományba vételi bizonylat, vagy - Webáruházból történő vásárlás esetén üzembe helyezési jegyzőkönyv vagy állományba vételi bizonylat)
B6: Hálózati adattároló - NAS | C6: db | D6: 1 | E6: 251400 | F6: 319278 | G6: =E6*D6 -> 251400 | H6: 2 fiókos, 2*4TB HDD | I6: Eszköznyilvántartási lap és alátámasztó dokumentumok - Üzembe helyezési okmány (pl. jegyzőkönyv), vagy - Üzembe helyezési okmány hiányában szállítólevél vagy átadás-átvételi jegyzőkönyv vagy állományba vételi bizonylat, vagy - Webáruházból történő vásárlás esetén üzembe helyezési jegyzőkönyv vagy állományba vételi bizonylat)
B7: Router | C7: db | D7: 1 | E7: 68200 | F7: 86614 | G7: =E7*D7 -> 68200 | H7: Vezetékes, 1 x WAN 2,5 Gibabit, 5 x LAN 1 Gigabit | I7: Eszköznyilvántartási lap és alátámasztó dokumentumok - Üzembe helyezési okmány (pl. jegyzőkönyv), vagy - Üzembe helyezési okmány hiányában szállítólevél vagy átadás-átvételi jegyzőkönyv vagy állományba vételi bizonylat, vagy - Webáruházból történő vásárlás esetén üzembe helyezési jegyzőkönyv vagy állományba vételi bizonylat)
B8: Mobiltelefon | C8: db | D8: 1 | E8: 212200 | F8: 269494 | G8: =E8*D8 -> 212200 | H8: 5G, 12 GB RAM, 256 GB tárhely | I8: Eszköznyilvántartási lap és alátámasztó dokumentumok - Üzembe helyezési okmány (pl. jegyzőkönyv), vagy - Üzembe helyezési okmány hiányában szállítólevél vagy átadás-átvételi jegyzőkönyv vagy állományba vételi bizonylat, vagy - Webáruházból történő vásárlás esetén üzembe helyezési jegyzőkönyv vagy állományba vételi bizonylat)
B9: Tablet | C9: db | D9: 1 | E9: 256500 | F9: 325755 | G9: =E9*D9 -> 256500 | H9: 8 GB RAM, 128 GB háttértár, legalább 11" kijelző, Bluetooth, GPS, kamera, 4G LTE/5G | I9: Eszköznyilvántartási lap és alátámasztó dokumentumok - Üzembe helyezési okmány (pl. jegyzőkönyv), vagy - Üzembe helyezési okmány hiányában szállítólevél vagy átadás-átvételi jegyzőkönyv vagy állományba vételi bizonylat, vagy - Webáruházból történő vásárlás esetén üzembe helyezési jegyzőkönyv vagy állományba vételi bizonylat)
B10: Multifunkciós nyomtató | C10: db | D10: 1 | E10: 152300 | F10: 193421 | G10: =E10*D10 -> 152300 | H10: lézernyomtató, szkenner, kétoldalas, színes, szkenner felbontás: 600*600 DPI; nyomtatási felbontás: 1200*1200 DPI, USB, Wifi/LAN | I10: Eszköznyilvántartási lap és alátámasztó dokumentumok - Üzembe helyezési okmány (pl. jegyzőkönyv), vagy - Üzembe helyezési okmány hiányában szállítólevél vagy átadás-átvételi jegyzőkönyv vagy állományba vételi bizonylat, vagy - Webáruházból történő vásárlás esetén üzembe helyezési jegyzőkönyv vagy állományba vételi bizonylat)
F13: Összesen, nettó | G13: =SUM(G3:G10) -> 1729800
F15: Összesen, bruttó | G15: =G13*1.27 -> 2196846

Sheet Szoftver
AA1: Fenntartási időszakra eső költségek (irányadó jelleggel, változatlan egységköltségekkel) | AF1: Fenntartási időszakra eső költségek (irányadó jelleggel, olcsóbb egységköltségekkel)
B2: Ssz. | C2: Fejlesztési célok | D2: Figyelembe vétel | E2: E | F2: Fejlesztési célok összetevői / műszaki követelmény | G2: Példa | H2: Összetevők teljesítésére vonatkozó előírások | I2: Mértékegység | J2: Egységköltség NETTÓ elszámoló (Ft) | K2: Egységköltség BRUTTÓ elszámoló (Ft) | M2: Alkalmazotti felhasználó szám | O2: Meglévő fejlesztésért kapott pont (ALAPADATOK fülön a bemeneti felmérés eredménye szerint) | P2: Ellentmondás a bemeneti mérés és a kiválasztott fejlesztési cél között | Q2: Ütközés más fejlesztési céllal | R2: Fejlesztésért kapott pont (Szoftver + Szolgáltatás, internet nélkül) | S2: Kate-gória | T2: Kapható támogatás (nettó FT) | V2: Kapható támogatás (bruttó FT) | X2: Alátámasztó dokumentum | Y2: Egységköltséghez kapcsolódó validálási elvárás | AA2: A fenntartási időszakra eső költség (1 főre) | AB2: A fenntartási időszakra eső költség (összes felhasználóra, havonta) | AC2: A fenntartási időszakra eső költség (összes felhasználóra, 1 évre) | AD2: A fenntartási időszakra eső költség (36 hónapra, összes felhasználóra) | AF2: Helyettesítő, alternatív vagy egyenértékű termék/szolgáltatás gördülő menü, válassz! | AG2: A fenntartási időszakra eső költség (1 főre, 1 hónapra) | AH2: A fenntartási időszakra eső költség (összes felhasználóra, havonta) | AI2: A fenntartási időszakra eső költség (összes felhasználóra, 1 évre) | AJ2: A fenntartási időszakra eső költség (36 hónapra, összes felhasználóra) | AL2: megtakarítás mértéke (36 hónapra, összes felhasználóra)
O4: =SUM(O5:O39) -> 2 | R4: =SUM(R5:R39) -> 5 | AA4: =SUM(AA7:AA11)+AA21 -> 11200 | AB4: =SUM(AB5:AB39) -> 466600 | AC4: =SUM(AC5:AC39) -> 5599200 | AD4: =SUM(AD5:AD39) -> 16797600 | AG4: =SUM(AG7:AG11)+AG21 -> 131028.32 | AH4: =SUM(AH5:AH39) -> 257418.32 | AI4: =SUM(AI5:AI39) -> 2489019.9 | AJ4: =SUM(AJ5:AJ39) -> 7467059.7 | AL4: =AD4-AJ4 -> 9330540.3
B5: 1. | C5: Internet | D5: Nem releváns | F5: Átalányköltség keretében van lehetőség elszámolni, mely a meghatározott egységköltségekbe már beépítésre kerültek. | M5: nem releváns | O5: =IF(Alapadatok!I22,1,0) -> 1 | P5: =IF(Alapadatok!I22,"Már rendelkezik vele!"," - ") -> Már rendelkezik vele! | X5: Átalányköltség keretében van lehetőség elszámolni (projektköltség 7%-a) | AA5: Nem releváns | AF5: Nem releváns | AL5: Nem releváns
B6: 2. | C6: Internet hozzáférés | D6: Nem releváns | F6: Átalányköltség keretében van lehetőség elszámolni, mely a meghatározott egységköltségekbe már beépítésre kerültek. | M6: nem releváns | O6: =IF(Alapadatok!I23,1,0) -> 0 | P6: =IF(Alapadatok!I23,"Már rendelkezik vele!"," - ") -> -
B7: 3. | C7: Távoli hozzáférés a következők valamelyikéhez: e-mail, dokumentumok, üzleti alkalmazás | D7: Pályázatból szerzi be | E7: =OR(IF(D7="Már rendelkezik vele",1,0),IF(D7="Pályázatból szerzi be",1,0),) -> TRUE | F7: SaaS irodai csomag | G7: M365 BB, OwnCloud, NextCloud, Onedrive, Sharepoint | H7: =IF(AND(D7="Nem releváns",D8="Nem releváns",D9="Nem releváns"), "Nem választott fejlesztési cél", IF(AND(E7,E8,E9), CONCATENATE('Egyéb költségek'!A7,CHAR(10),"TELJESÜL"), CONCATENATE('Egyéb költségek'!A7,CHAR(10),"NEM TELJESÜL") ) ) -> A fejlesztési célon belül MINDEN összetevő teljesítése KÖTELEZŐ. TELJESÜL | I7: felhasználó/hó | J7: 5900 | K7: 7493 | M7: 1 | O7: =IF(Alapadatok!I24,1,0) -> 1 | P7: =IF(AND(O7=1,OR(E7,E8,E9)),"VAN","NINCS") -> VAN | Q7: =IF(AND(E7,E8,E9,E14),"VAN","NINCS") -> NINCS | R7: =IF(AND(E7,E8,E9,P7="NINCS"),1,"Nem adható pont") -> Nem adható pont | S7: sw | T7: =IF(AND($D7="Pályázatból szerzi be",O7=0),$M7*Alapadatok!$H$16*J7," - ") -> - | V7: =IF($D7="Pályázatból szerzi be",$M7*Alapadatok!$H$16*K7,"") -> 89916 | X7: Szerződés vagy szerződés hiányában visszaigazolt írásos megrendelő | Y7: A SaaS irodai csomag esetében validálni szükséges az elszámolni kívánt felhasználói darabszámot és a hónapok meglétét. | AA7: =IF(AND(E7,E8,E9,D7="Pályázatból szerzi be"),J7,0) -> 5900 | AB7: =AA7*M7 -> 5900 | AC7: =AB7*12 -> 70800 | AD7: =AB7*36 -> 212400 | AF7: Exchange Plan 1 | AG7: =_xlfn.XLOOKUP(AF7,'Alternatív termékek'!A5:A21,'Alternatív termékek'!B5:B21,"HIBA") -> 1729.1976 | AH7: =IF(AND(E7,E8,E9,D7="Pályázatból szerzi be"),M7*AG7,0) -> 1729.1976 | AI7: =AH7*12 -> 20750.371 | AJ7: =AH7*36 -> 62251.114 | AL7: =AD7-AJ7 -> 150148.89
D8: Pályázatból szerzi be | E8: =OR(IF(D8="Már rendelkezik vele",1,0),IF(D8="Pályázatból szerzi be",1,0),) -> TRUE | F8: Domain regisztráció | G8: Havidíjas továbbadott szolgáltatás | I8: hó | J8: 200 | K8: 254 | M8: nem releváns | S8: sw | T8: =IF(D8="Pályázatból szerzi be",Alapadatok!$H$16*J8,"") -> 2400 | V8: =IF($D8="Pályázatból szerzi be",Alapadatok!$H$16*K8,"") -> 3048 | Y8: A Domain regisztráció esetében validálni szükséges az elszámolni kívánt hónapok meglétét. | AB8: =IF(AND(E7,E8,E9,D8="Pályázatból szerzi be"),J8,0) -> 200 | AC8: =AB8*12 -> 2400 | AD8: =AB8*36 -> 7200 | AF8: Nincs | AH8: =IF(AND(E7,E8,E9,D7="Pályázatból szerzi be"),J8,0) -> 200 | AI8: =AH8*12 -> 2400 | AJ8: =AH8*36 -> 7200 | AL8: =AD8-AJ8 -> 0
D9: Pályázatból szerzi be | E9: =OR(IF(D9="Már rendelkezik vele",1,0),IF(D9="Pályázatból szerzi be",1,0),) -> TRUE | F9: Havidíjas IT-üzemeltetés (alapszint) | G9: Havidíjas szolgáltatás | I9: hó | J9: 127300 | K9: 161671 | M9: nem releváns | S9: szolg | T9: =IF(D9="Pályázatból szerzi be",Alapadatok!$H$16*J9,"") -> 1527600 | V9: =IF($D9="Pályázatból szerzi be",Alapadatok!$H$16*K9,"") -> 1940052 | Y9: A Havidíjas IT üzemeltetés esetében validálni szükséges az elszámolni kívánt hónapok meglétét. | AB9: =IF(AND(E7,E8,E9,D9="Pályázatból szerzi be"),J9,0) -> 127300 | AC9: =AB9*12 -> 1527600 | AD9: =AB9*36 -> 4582800 | AF9: Megegyezés szerint, pl.: | AG9: 100000 | AH9: =IF(AND(E7,E8,E9,D9="Pályázatból szerzi be"),AG9,0) -> 100000 | AI9: =AH9*12 -> 1200000 | AJ9: =AH9*36 -> 3600000 | AL9: =AD9-AJ9 -> 982800
B10: 4. | C10: Online (távoli) megbeszélések tartása | D10: Pályázatból szerzi be | E10: =OR(IF(D10="Már rendelkezik vele",1,0),IF(D10="Pályázatból szerzi be",1,0),) -> TRUE | F10: Videókonferencia platform | G10: Teams, Webex | H10: =IF(AND(D10="Nem releváns",D11="Nem releváns"), "Nem választott fejlesztési cél", IF(AND(E10,E11), CONCATENATE('Egyéb költségek'!$A$7,CHAR(10),"TELJESÜL"), CONCATENATE('Egyéb költségek'!$A$7,CHAR(10),"NEM TELJESÜL") ) ) -> A fejlesztési célon belül MINDEN összetevő teljesítése KÖTELEZŐ. TELJESÜL | I10: felhasználó/hó | J10: 5300 | K10: 6731 | M10: 1 | O10: =IF(Alapadatok!I25,1,0) -> 0 | P10: =IF(AND(O10=1,OR(E10,E11)),"VAN","NINCS") -> NINCS | R10: =IF(AND(E10,E11,P10="NINCS"),1,"Nem adható pont") -> 1 | S10: sw | T10: =IF(AND(D10="Pályázatból szerzi be",D11="Pályázatból szerzi be"),M10*Alapadatok!$H$16*J10,"") -> 63600 | V10: =IF($D10="Pályázatból szerzi be",$M10*Alapadatok!$H$16*K10,"") -> 80772 | X10: Szerződés vagy szerződés hiányában visszaigazolt írásos megrendelő. Képernyőkép vagy videofelvétel az online formátumú üzleti megbeszélésekről (legalább 4 darab megbeszélés / év, eltérő napon megtartva) | Y10: A Videókonferencia platform esetében validálni szükséges az elszámolni kívánt (teljesült) felhasználói darabszámot és a hónapok meglétét. | AA10: =IF(AND(E10,E11,D10="Pályázatból szerzi be"),J10,0) -> 5300 | AB10: =AA10*M10 -> 5300 | AC10: =AB10*12 -> 63600 | AD10: =AB10*36 -> 190800 | AF10: MS Teams | AG10: =_xlfn.XLOOKUP(AF10,'Alternatív termékek'!A21:A25,'Alternatív termékek'!B21:B25,"HIBA") -> 3299.127 | AH10: =IF(AND(E10,E11,D10="Pályázatból szerzi be"),M10*AG10,0) -> 3299.127 | AI10: =AH10*12 -> 39589.524 | AJ10: =AH10*36 -> 118768.57 | AL10: =AD10-AJ10 -> 72031.428
D11: Pályázatból szerzi be | E11: =OR(IF(D11="Már rendelkezik vele",1,0),IF(D11="Pályázatból szerzi be",1,0),) -> TRUE | F11: Bevezetési, üzemeltetési szolgáltatás | G11: Havidíjas szolgáltatás | I11: hó | J11: 53000 | K11: 67310 | M11: nem releváns | S11: szolg | T11: =IF(AND(D10="Pályázatból szerzi be",D11="Pályázatból szerzi be"),Alapadatok!$H$16*J11,"") -> 636000 | V11: =IF($D11="Pályázatból szerzi be",Alapadatok!$H$16*K11,"") -> 807720 | Y11: A Bevezetési, üzemeltetési szolgáltatás esetében validálni szükséges a szolgáltatás igénybevételének hónapjait. | AB11: =IF(AND(E10,E11,D11="Pályázatból szerzi be"),J11,0) -> 53000 | AC11: =AB11*12 -> 636000 | AD11: =AB11*36 -> 1908000 | AF11: Megegyezés szerint, pl.: | AG11: 20000 | AH11: =IF(AND(E10,E11,D11="Pályázatból szerzi be"),AG11,0) -> 20000 | AI11: =AH11*12 -> 240000 | AJ11: =AH11*36 -> 720000 | AL11: =AD11-AJ11 -> 1188000
B12: 5. | C12: IKT-képzés biztosítása az alkalmazottaknak | D12: Nem releváns | E12: =OR(IF(D12="Már rendelkezik vele",1,0),IF(D12="Pályázatból szerzi be",1,0),) -> FALSE | F12: IKT-alapképzés | G12: Felnőttképzési akkreditáció szükséges! | H12: A fejlesztési célon belül legalább EGY összetevő teljesítése KÖTELEZŐ. A másik összetevő teljesítése VÁLASZTHATÓ. | I12: fő | J12: 76300 | K12: 96901 | M12: 4 | O12: =IF(Alapadatok!I26,1,0) -> 0 | P12: =IF(AND(O12=1,OR(E12,E13)),"VAN","NINCS") -> NINCS | R12: =IF(AND(E12,P12="NINCS"),1,"Nem adható pont") -> Nem adható pont | S12: okt | T12: =IF(D12="Pályázatból szerzi be",M12*J12,0) -> 0 | V12: =IF(D12="Pályázatból szerzi be",M12*K12,"") | X12: Képzési tematika, segédanyagok, jelenléti ív vagy képernyőkép vagy videofelvétel a szereplők, időpont, képzés tárgyának egyértelmű azonosíthatóságával | Y12: A képzések esetében validálni szükséges az elszámolni kívánt képzést elvégzők számát. | AA12: Nem releváns | AF12: Nem releváns, nincs fenntartási kötelezettség | AL12: Nem releváns
D13: Nem releváns | E13: =OR(IF(D13="Már rendelkezik vele",1,0),IF(D13="Pályázatból szerzi be",1,0),) -> FALSE | F13: Haladó digitális készségfejlesztés | G13: Felnőttképzési akkreditáció szükséges! | I13: fő | J13: 191100 | K13: 242697 | M13: 4 | S13: okt | T13: =IF(D13="Pályázatból szerzi be",M13*J13,0) -> 0 | V13: =IF(D13="Pályázatból szerzi be",M13*K13,"")
B14: 6. | C14: IKT-szakember igénybevétele | D14: Nem releváns | E14: =OR(IF(D14="Már rendelkezik vele",1,0),IF(D14="Pályázatból szerzi be",1,0),) -> FALSE | F14: IKT-szakember igénybevétele | G14: Akár havi 40-80 óra | H14: A fejlesztési célon belül az összetevő teljesítése KÖTELEZŐ. | I14: óra | J14: 9200 | K14: 11684 | M14: 115 | O14: =IF(Alapadatok!I27,1,0) -> 0 | P14: =IF(AND(O14=1,E14),"VAN","NINCS") -> NINCS | Q14: =IF(AND(E7,E8,E9,E14),"VAN","NINCS") -> NINCS | R14: =IF(AND(E14,P14="NINCS"),1,"Nem adható pont") -> Nem adható pont | S14: szolg | T14: =IF(D14="Pályázatból szerzi be",M14*J14,"") | V14: =IF(D14="Pályázatból szerzi be",M14*K14,"") | X14: Szerződés, igazolás a teljesített órákról. | Y14: Az IKT szakember igénybevétele esetében validálni szükséges az elszámolni kívánt (teljesült) órák számát. | AA14: =IF(D14="Pályázatból szerzi be","Megegyezés szerint","Nem releváns, nem volt ilyen fejlesztési cél kiválasztva") -> Nem releváns, nem volt ilyen fejlesztési cél kiválasztva | AF14: =IF(D14="Pályázatból szerzi be","Megegyezés szerint","Nem releváns, nem volt ilyen fejlesztési cél kiválasztva") -> Nem releváns, nem volt ilyen fejlesztési cél kiválasztva | AL14: Nem releváns
B15: 7. | C15: Alkalmazottak tájékoztatása az IKT-biztonsággal kapcsolatos kötelezettségeikről | D15: Nem releváns | E15: =OR(IF(D15="Már rendelkezik vele",1,0),IF(D15="Pályázatból szerzi be",1,0),) -> FALSE | F15: IKT-biztonsági képzés | G15: Többféle lehetőség is rendelkezésre áll | H15: A fejlesztési célon belül az összetevő teljesítése KÖTELEZŐ. | I15: fő | J15: 207100 | K15: 263017 | M15: 5 | O15: =IF(Alapadatok!I28,1,0) -> 0 | P15: =IF(AND(O15=1,E15),"VAN","NINCS") -> NINCS | R15: =IF(AND(E15,P15="NINCS"),1,"Nem adható pont") -> Nem adható pont | S15: okt | T15: =IF(D15="Pályázatból szerzi be",M15*J15,0) -> 0 | V15: =IF(D15="Pályázatból szerzi be",M15*K15,"") | X15: Jelenléti ív vagy képző szerv igazolása a képzésen való részvételről vagy online képzés esetén képernyőkép a képzésről. | Y15: Az IKT-biztonsági képzés esetében validálni szükséges az elszámolni kívánt képzést elvégzők számát. | AA15: Nem releváns, nincs fenntartási kötelezettség | AF15: Nem releváns, nincs fenntartási kötelezettség | AL15: Nem releváns
B16: 8. | C16: Legalább 3 IKT-biztonsági intézkedés alkalmazása | D16: Nem releváns | E16: =OR(IF(D16="Már rendelkezik vele",1,0),IF(D16="Pályázatból szerzi be",1,0),) -> FALSE | F16: Végpontvédelmi licenc | G16: Norton, ESET, Heimdal | H16: =IF(AND(E16,E17),CONCATENATE('Egyéb költségek'!A7,CHAR(10),"TELJESÜL"),CONCATENATE('Egyéb költségek'!A7,CHAR(10),"NEM TELJESÜL")) -> A fejlesztési célon belül MINDEN összetevő teljesítése KÖTELEZŐ. NEM TELJESÜL | I16: db/hó | J16: 1400 | K16: 1778 | M16: 3 | O16: =IF(Alapadatok!I29,1,0) -> 0 | P16: =IF(AND(O16=1,OR(E16,E17)),"VAN","NINCS") -> NINCS | R16: =IF(AND(E16,E17,P16="NINCS"),1,"Nem adható pont") -> Nem adható pont | S16: sw | T16: =IF(D16="Pályázatból szerzi be",M16*J16*Alapadatok!$H$16,"") | V16: =IF($D16="Pályázatból szerzi be",$M16*Alapadatok!$H$16*K16,"") | X16: Szerződés vagy szerződés hiányában visszaigazolt írásos megrendelő. | Y16: A Végpontvédelmi licenc, valamint a Biztonsági mentés esetében validálni szükséges az elszámolni kívánt hónapok és eszközök számát. | AA16: =IF(AND(E16,E17,D16="Pályázatból szerzi be"),J16,0) -> 0 | AB16: =AA16*M16 -> 0 | AC16: =AB16*12 -> 0 | AD16: =AB16*36 -> 0 | AF16: ESET Nod32 | AG16: =_xlfn.XLOOKUP(AF16,'Alternatív termékek'!A26:A36,'Alternatív termékek'!B26:B36,"HIBA") -> 1800 | AH16: =IF(AND(E16,E17),AG16*M16,0) -> 0 | AI16: =AH16*12 -> 0 | AJ16: =AH16*36 -> 0 | AL16: =IF(AND(E16,E17),AD16-AJ16,"Nem releváns") -> Nem releváns
D17: Nem releváns | E17: =OR(IF(D17="Már rendelkezik vele",1,0),IF(D17="Pályázatból szerzi be",1,0),) -> FALSE | F17: Biztonsági mentés | G17: Synology, OneDrive | I17: db/hó | J17: 3000 | K17: 3810 | M17: 3 | S17: sw | T17: =IF(D17="Pályázatból szerzi be",M17*J17*Alapadatok!$H$16,"") | V17: =IF($D17="Pályázatból szerzi be",$M17*Alapadatok!$H$16*K17,"") | AA17: =IF(AND(E16,E17,D17="Pályázatból szerzi be"),J17,0) -> 0 | AB17: =IF(AND(E16,E17,D17="Pályázatból szerzi be"),J17*M17,0) -> 0 | AC17: =AB17*12 -> 0 | AD17: =AB17*36 -> 0 | AF17: Backup 1 | AG17: =_xlfn.XLOOKUP(AF17,'Alternatív termékek'!A37:A41,'Alternatív termékek'!B37:B41,"HIBA") -> 2800 | AH17: =IF(AND(E16,E17),AG17*M17,0) -> 0 | AI17: =AH17*12 -> 0 | AJ17: =AH17*36 -> 0 | AL17: =IF(AND(E16,E17),AD17-AJ17,"Nem releváns") -> Nem releváns
B18: 9. | C18: IKT-biztonsági gyakorlatokat, eljárásokat rögzítő dokumentumok megléte | D18: Nem releváns | E18: =OR(IF(D18="Már rendelkezik vele",1,0),IF(D18="Pályázatból szerzi be",1,0),) -> FALSE | F18: IBSZ (Informatikai Biztonsági Szabályzat) kidolgozása | H18: A fejlesztési célon belül az összetevő teljesítése KÖTELEZŐ. | I18: egyszeri költség | J18: 524300 | K18: 665861 | M18: nem releváns | O18: =IF(Alapadatok!I30,1,0) -> 0 | P18: =IF(AND(O18=1,OR(E18,E19,E20,E21)),"VAN","NINCS") -> NINCS | R18: =IF(AND(OR(E18,E19,E20,E21),P18="NINCS"),1,"Nem adható pont") -> Nem adható pont | S18: szolg | T18: =IF(D18="Pályázatból szerzi be",J18,"") | V18: =IF(D18="Pályázatból szerzi be",K18,"") | X18: Szerződés vagy szerződés hiányában visszaigazolt írásos megrendelő. Elkészült GDPR alapfelmérés és nyilvántartás, valamint IBSZ. Képzés esetében jelenléti ív vagy képző szerv igazolása a képzésen való részvételről vagy online képzés esetén képernyőkép a képzésről. | Y18: A GDPR alapfelmérés és nyilvántartás és az IBSZ kidolgozása és információbiztonsági felelős szolgáltatás esetében validálni szükséges a szolgáltatások megvalósulását, az incidenskezelési terv és oktatás esetében a képzettek számát, a Digitális aláírás szolgáltatás esetében pedig a hónapok és a felhasználók számát. | AA18: Nem releváns, nincs fenntartási kötelezettség | AF18: Nem releváns, nincs fenntartási kötelezettség | AL18: Nem releváns
D19: Nem releváns | E19: =OR(IF(D19="Már rendelkezik vele",1,0),IF(D19="Pályázatból szerzi be",1,0),) -> FALSE | F19: GDPR alapfelmérés és adatkezelési nyilvántartás | H19: A fejlesztési célon belül BÁRMELYIK és BÁRMENNYI összetevő teljesítése VÁLASZTHATÓ. | I19: egyszeri költség | J19: 257900 | K19: 327533 | M19: nem releváns | S19: szolg | T19: =IF(D19="Pályázatból szerzi be",J19,"") | V19: =IF(D19="Pályázatból szerzi be",K19,"") | AA19: Nem releváns, nincs fenntartási kötelezettség
D20: Nem releváns | E20: =OR(IF(D20="Már rendelkezik vele",1,0),IF(D20="Pályázatból szerzi be",1,0),) -> FALSE | F20: Incidenskezelési terv és oktatás | I20: fő | J20: 294300 | K20: 373761 | M20: 1 | S20: szolg | T20: =IF(D20="Pályázatból szerzi be",M20*J20,"") | V20: =IF(D20="Pályázatból szerzi be",M20*K20,"") | AA20: Nem releváns, nincs fenntartási kötelezettség
D21: Nem releváns | E21: =OR(IF(D21="Már rendelkezik vele",1,0),IF(D21="Pályázatból szerzi be",1,0),) -> FALSE | F21: Digitális aláírás szolgáltatás | G21: Microsec, Netlock | I21: felhasználó/hó | J21: 5200 | K21: 6604 | M21: 1 | S21: szolg | T21: =IF(D21="Pályázatból szerzi be",M21*J21*Alapadatok!H16,"") | V21: =IF($D21="Pályázatból szerzi be",$M21*Alapadatok!$H$16*K21,"") | AA21: =IF(AND(E21,E22,D21="Pályázatból szerzi be"),J21,0) -> 0 | AB21: =AA21*M21 -> 0 | AC21: =AB21*12 -> 0 | AD21: =AB21*36 -> 0 | AF21: Netlock | AG21: =_xlfn.XLOOKUP(AF21,'Alternatív termékek'!A42:A46,'Alternatív termékek'!B42:B46,"HIBA") -> 6000 | AH21: =IF(AND(E21,D21="Pályázatból szerzi be"),AG21*M21,0) -> 0 | AI21: =AH21*12 -> 0 | AJ21: =AH21*36 -> 0 | AL21: =AD21-AJ21 -> 0
B22: 10. | C22: Saját weboldallal/honlappal való rendelkezés | D22: Pályázatból szerzi be | E22: =OR(IF(D22="Már rendelkezik vele",1,0),IF(D22="Pályázatból szerzi be",1,0),) -> TRUE | F22: Saját weboldal kialakítása | G22: WP | H22: =IF(AND(D22="Nem releváns",D23="Nem releváns",D24="Nem releváns",D25="Nem releváns"), "Nem választott fejlesztési cél", IF(AND(E22,E23,E24,E25), CONCATENATE('Egyéb költségek'!A7,CHAR(10),"TELJESÜL"), CONCATENATE('Egyéb költségek'!A7,CHAR(10),"NEM TELJESÜL") ) ) -> A fejlesztési célon belül MINDEN összetevő teljesítése KÖTELEZŐ. TELJESÜL | I22: egyszeri költség | J22: 345100 | K22: 438277 | M22: nem releváns | O22: =IF(Alapadatok!I31,1,0) -> 0 | P22: =IF(AND(O22=1,OR(E22,E23,E24,E25)),"VAN","NINCS") -> NINCS | R22: =IF(AND(E22,E23,E24,E25,P22="NINCS"),1,"Nem adható pont") -> 1 | S22: sw | T22: =IF(D22="Pályázatból szerzi be",J22,"") -> 345100 | V22: =IF(D22="Pályázatból szerzi be",K22,"") -> 438277 | X22: Szerződés vagy szerződés hiányában visszaigazolt írásos megrendelő, valamint a weboldal elérhetősége (link). | Y22: A Saját weboldal működése, mely a digitális szintemelkedés teljesülésének vizsgálata során validálásra kerül egyértelművé teszi a weboldal kialakítását, ezért a Saját weboldal kialakítása esetében külön validáció nem szükséges. | AA22: Nem releváns, a fejlesztés elején megtörtént | AF22: Nem releváns, a fejlesztés elején megtörtént | AL22: Nem releváns
D23: Pályázatból szerzi be | E23: =OR(IF(D23="Már rendelkezik vele",1,0),IF(D23="Pályázatból szerzi be",1,0),) -> TRUE | F23: Karbantartás/frissítés | I23: hó | J23: 10100 | K23: 12827 | M23: nem releváns | S23: sw | T23: =IF(D23="Pályázatból szerzi be",J23*Alapadatok!$H$16,"") -> 121200 | V23: =IF($D23="Pályázatból szerzi be",Alapadatok!$H$16*K23,"") -> 153924 | Y23: A Karbantartás/frissítés, a Webtárhely, valamint az SSL tanúsítvány esetében validálni szükséges az elszámolni kívánt (teljesült) hónapok számát. | AB23: =IF(AND(E22,E23,E24,E25,D23="Pályázatból szerzi be"),J23,0) -> 10100 | AC23: =AB23*12 -> 121200 | AD23: =AB23*36 -> 363600 | AH23: =IF(AND(E22,E23,E24,E25,D23="Pályázatból szerzi be"),3000,0) -> 3000 | AI23: =AH23*12 -> 36000 | AJ23: =AH23*36 -> 108000 | AL23: =AD23-AJ23 -> 255600
D24: Pályázatból szerzi be | E24: =OR(IF(D24="Már rendelkezik vele",1,0),IF(D24="Pályázatból szerzi be",1,0),) -> TRUE | F24: Webtárhely | I24: hó | J24: 1900 | K24: 2413 | M24: nem releváns | S24: sw | T24: =IF(D24="Pályázatból szerzi be",J24*Alapadatok!$H$16,"") -> 22800 | V24: =IF($D24="Pályázatból szerzi be",Alapadatok!$H$16*K24,"") -> 28956 | AB24: =IF(AND(E22,E23,E24,E25,D24="Pályázatból szerzi be"),J24,0) -> 1900 | AC24: =AB24*12 -> 22800 | AD24: =AB24*36 -> 68400 | AH24: =IF(AND(E22,E23,E24,E25,D24="Pályázatból szerzi be"),1000,0) -> 1000 | AI24: =AH24*12 -> 12000 | AJ24: =AH24*36 -> 36000 | AL24: =AD24-AJ24 -> 32400
D25: Pályázatból szerzi be | E25: =OR(IF(D25="Már rendelkezik vele",1,0),IF(D25="Pályázatból szerzi be",1,0),) -> TRUE | F25: SSL tanúsítvány | I25: hó | J25: 600 | K25: 762 | M25: nem releváns | S25: sw | T25: =IF(D25="Pályázatból szerzi be",J25*Alapadatok!$H$16,"") -> 7200 | V25: =IF($D25="Pályázatból szerzi be",Alapadatok!$H$16*K25,"") -> 9144 | AB25: =IF(AND(E22,E23,E24,E25,D25="Pályázatból szerzi be"),J25,0) -> 600 | AC25: =AB25*12 -> 7200 | AD25: =AB25*36 -> 21600 | AH25: =IF(AND(E22,E23,E24,E25,D25="Pályázatból szerzi be"),300,0) -> 300 | AI25: =AH25*12 -> 3600 | AJ25: =AH25*36 -> 10800 | AL25: =AD25-AJ25 -> 10800
B26: 11. | C26: Bármilyen közösségi média használata | D26: Nem releváns | E26: =OR(IF(D26="Már rendelkezik vele",1,0),IF(D26="Pályázatból szerzi be",1,0),) -> FALSE | F26: Tartalomgyártás | G26: fb, TikTok, Instagram | H26: A fejlesztési célon belül az összetevő teljesítése KÖTELEZŐ. | I26: hó | J26: 74900 | K26: 95123 | M26: nem releváns | O26: =IF(Alapadatok!I32,1,0) -> 0 | P26: =IF(AND(O26=1,E26),"VAN","NINCS") -> NINCS | Q26: =IF(AND(E26,E27),"VAN","NINCS") -> NINCS | R26: =IF(AND(E26,P22="NINCS"),1,"Nem adható pont") -> Nem adható pont | S26: sw | T26: =IF(D26="Pályázatból szerzi be",J26*Alapadatok!$H$16,"") | V26: =IF($D26="Pályázatból szerzi be",Alapadatok!$H$16*K26,"") | X26: Szerződés vagy szerződés hiányában visszaigazolt írásos megrendelő | Y26: A Tartalomgyártás esetében validálni szükséges az elszámolni kívánt (teljesült) hónapok számát | AB26: =IF(AND(E26,D26="Pályázatból szerzi be"),J26,0) -> 0 | AC26: =AB26*12 -> 0 | AD26: =AB26*36 -> 0 | AH26: 50000 | AI26: =IF(AND(E26,D26="Pályázatból szerzi be"),AH2612,0) -> 0 | AJ26: =AI26*3 -> 0 | AL26: =IF(AND(E26,D26="Pályázatból szerzi be"),AD26-AJ26,"Nem releváns") -> Nem releváns
B27: 12. | C27: Kettő vagy több típusú közösségi média használata | D27: Pályázatból szerzi be | E27: =OR(IF(D27="Már rendelkezik vele",1,0),IF(D27="Pályázatból szerzi be",1,0),) -> TRUE | F27: Online jelenlét és hirdetések | H27: A fejlesztési célon belül az összetevő teljesítése KÖTELEZŐ. | I27: hó | J27: 96300 | K27: 122301 | M27: nem releváns | O27: =IF(Alapadatok!I33,1,0) -> 0 | P27: =IF(AND(O27=1,E27),"VAN","NINCS") -> NINCS | Q27: =IF(AND(E26,E27),"VAN","NINCS") -> NINCS | R27: =IF(AND(E27,P27="NINCS"),1,"Nem adható pont") -> 1 | S27: sw | T27: =IF(D27="Pályázatból szerzi be",J27*Alapadatok!$H$16,"") -> 1155600 | V27: =IF($D27="Pályázatból szerzi be",Alapadatok!$H$16*K27,"") -> 1467612 | X27: Szerződés vagy szerződés hiányában visszaigazolt írásos megrendelő Képzés esetében jelenléti ív vagy képző szerv igazolása a képzésen való részvételről vagy online képzés esetén képernyőkép a képzésről. | Y27: Az Online jelenlét és hirdetések kezelése esetében validálni szükséges az elszámolni kívánt (teljesült) hónapok számát. | AA27: =IF(AND(E27,D27="Pályázatból szerzi be"),J27,0) -> 96300 | AB27: =IF(AND(E27,D27="Pályázatból szerzi be"),J27,0) -> 96300 | AC27: =AB27*12 -> 1155600 | AD27: =AB27*36 -> 3466800 | AF27: Megegyezés szerint, pl.: | AG27: 60000 | AH27: =IF(AND(E27,E28,D27="Pályázatból szerzi be"),AG27,0) -> 60000 | AI27: =AH27*12 -> 720000 | AJ27: =AI27*3 -> 2160000 | AL27: =IF(AND(E27,D27="Pályázatból szerzi be"),AD27-AJ27,"Nem releváns") -> 1306800
D28: Pályázatból szerzi be | E28: =OR(IF(D28="Már rendelkezik vele",1,0),IF(D28="Pályázatból szerzi be",1,0),) -> TRUE | F28: Képzés | H28: Az összetevő teljesítése VÁLASZTHATÓ. | I28: fő | J28: 374500 | K28: 475615 | M28: 1 | S28: okt | T28: =IF(D28="Pályázatból szerzi be",J28,"") -> 374500 | V28: =IF(D28="Pályázatból szerzi be",K28,"") -> 475615 | Y28: A Képzés esetében validálni szükséges a képzettek számát. | AA28: Nem releváns, nincs fenntartási kötelezettség | AF28: Nem releváns, nincs fenntartási kötelezettség a képzésre | AL28: Nem releváns
B29: 13. | C29: Bármilyen fizetős felhőszolgáltatás használata | D29: Pályázatból szerzi be | E29: =OR(IF(D29="Már rendelkezik vele",1,0),IF(D29="Pályázatból szerzi be",1,0),) -> TRUE | F29: Virtuális szerver (IaaS) | H29: =IF(AND(D29="Nem releváns",D30="Nem releváns",D31="Nem releváns"), "Nem választott fejlesztési cél", IF(AND(E29,E30,E31), CONCATENATE('Egyéb költségek'!A7,CHAR(10),"TELJESÜL"), CONCATENATE('Egyéb költségek'!A7,CHAR(10),"NEM TELJESÜL") ) ) -> A fejlesztési célon belül MINDEN összetevő teljesítése KÖTELEZŐ. TELJESÜL | I29: hó | J29: 21800 | K29: 27686 | M29: nem releváns | O29: =IF(Alapadatok!I34,1,0) -> 0 | P29: =IF(AND(O29=1,E29),"VAN","NINCS") -> NINCS | S29: sw | T29: =IF(D29="Pályázatból szerzi be",J29*Alapadatok!$H$16,"") -> 261600 | V29: =IF($D29="Pályázatból szerzi be",Alapadatok!$H$16*K29,"") -> 332232 | X29: Szerződés vagy szerződés hiányában visszaigazolt írásos megrendelő. | Y29: A Virtuális szerver (IaaS), Adattárolás és mentés felhőben esetében validálni szükséges az elszámolni kívánt (teljesült) hónapok számát | AB29: =IF(AND(E29,E30,E31,D29="Pályázatból szerzi be"),J29,0) -> 21800 | AC29: =AB29*12 -> 261600 | AD29: =AB29*36 -> 784800 | AF29: Átgondolandó | AL29: =IF(AND(E29,D29="Pályázatból szerzi be"),AD29-AJ29,"Nem releváns") -> 784800
D30: Pályázatból szerzi be | E30: =OR(IF(D30="Már rendelkezik vele",1,0),IF(D30="Pályázatból szerzi be",1,0),) -> TRUE | F30: Adattárolás és mentés (felhő storage) | I30: hó | J30: 109100 | K30: 138557 | M30: nem releváns | S30: sw | T30: =IF(D30="Pályázatból szerzi be",J30*Alapadatok!$H$16,"") -> 1309200 | V30: =IF($D30="Pályázatból szerzi be",Alapadatok!$H$16*K30,"") -> 1662684 | AB30: =IF(AND(E30,E31,E29,D30="Pályázatból szerzi be"),J30,0) -> 109100 | AC30: =AB30*12 -> 1309200 | AD30: =AB30*36 -> 3927600 | AL30: =IF(AND(E30,D30="Pályázatból szerzi be"),AD30-AJ30,"Nem releváns") -> 3927600
D31: Pályázatból szerzi be | E31: =OR(IF(D31="Már rendelkezik vele",1,0),IF(D31="Pályázatból szerzi be",1,0),) -> TRUE | F31: Bevezetés, testre szabás | I31: egyszeri költség | J31: 1379800 | K31: 1752346 | M31: nem releváns | S31: szolg | T31: =IF(D31="Pályázatból szerzi be",J31,"") -> 1379800 | V31: =IF(D31="Pályázatból szerzi be",K31,"") -> 1752346 | Y31: A Virtuális szerver (IaaS), Adattárolás és mentés felhőben működése egyértelművé teszi a Bevezetés, testreszabás megtörténtét ezért utóbbit külön validálni nem szükséges. | AA31: Nem releváns, nincs fenntartási kötelezettség | AF31: Nem releváns, nincs fenntartási kötelezettség a bevezetésre | AL31: Nem releváns
D32: Pályázatból szerzi be | E32: =OR(IF(D32="Már rendelkezik vele",1,0),IF(D32="Pályázatból szerzi be",1,0),) -> TRUE | F32: MI szolgáltatás | G32: You, ChatGPT, Claude | H32: Az összetevő teljesítése VÁLASZTHATÓ. | I32: felhasználó/hó | J32: 14400 | K32: 18288 | M32: 1 | R32: 1 | S32: sw | T32: =IF(D32="Pályázatból szerzi be",J32*Alapadatok!$H$16*M32,"") -> 172800 | V32: =IF($D32="Pályázatból szerzi be",$M32*Alapadatok!$H$16*K32,"") -> 219456 | Y32: MI szolgáltatás esetében validálni szükséges az elszámolni kívánt (teljesült) hónapok, valamint a felhasználók számát. | AA32: =IF(AND(E32,D32="Pályázatból szerzi be"),J32,0) -> 14400 | AB32: =AA32*M32 -> 14400 | AC32: =AB32*12 -> 172800 | AD32: =AB32*36 -> 518400 | AF32: ChatGPT | AG32: =_xlfn.XLOOKUP(AF32,'Alternatív termékek'!A47:A57,'Alternatív termékek'!B47:B57,"HIBA") -> 7890 | AH32: =IF(AND(E32,D32="Pályázatból szerzi be"),AG32*M32,0) -> 7890 | AI32: =AH32*12 -> 94680 | AJ32: =AI32*3 -> 284040 | AL32: =AD32-AJ32 -> 234360
B33: 15. | C33: Vállalati erőforrás-tervezési (ERP) megoldás használata | D33: Nem releváns | E33: =OR(IF(D33="Már rendelkezik vele",1,0),IF(D33="Pályázatból szerzi be",1,0),) -> FALSE | F33: ERP szoftverlicenc / előfizetés (SaaS modell) | H33: =IF(AND(D33="Nem releváns",D34="Nem releváns"), "Nem választott fejlesztési cél", IF(AND(E33,E34), CONCATENATE('Egyéb költségek'!A7,CHAR(10),"TELJESÜL"), CONCATENATE('Egyéb költségek'!A7,CHAR(10),"NEM TELJESÜL") ) ) -> Nem választott fejlesztési cél | I33: felhasználó/hó | J33: 24800 | K33: 31496 | M33: 1 | O33: =IF(Alapadatok!I36,1,0) -> 0 | P33: =IF(AND(O33=1,E33,E34),"VAN","NINCS") -> NINCS | R33: =IF(AND(E33,E34,P33="NINCS"),1,"Nem adható pont") -> Nem adható pont | S33: sw | T33: =IF(D33="Pályázatból szerzi be",J33*Alapadatok!$H$16*M33,"") | V33: =IF($D33="Pályázatból szerzi be",$M33*Alapadatok!$H$16*K33,"") | X33: Szerződés vagy szerződés hiányában visszaigazolt írásos megrendelő. | Y33: Az ERP szoftverlicenc / előfizetés esetében validálni szükséges az elszámolni kívánt (teljesült) felhasználó számot és a hónap meglétét, a Bevezetés, testreszabás, felhasználói oktatás szolgáltatás esetén pedig az ERP rendszer működését (ami a digitális intenzitási szint emelkedésének validálása során megtörténik). | AA33: =IF(AND(E33,D33="Pályázatból szerzi be"),J33,0) -> 0 | AB33: =AA33*M33 -> 0 | AC33: =AB33*12 -> 0 | AD33: =AB33*36 -> 0 | AG33: =IF(AND(E33,D33="Pályázatból szerzi be"),J33,0) -> 0 | AH33: =AG33*M33 -> 0 | AI33: =AH33*12 -> 0 | AJ33: =AH33*36 -> 0 | AL33: =IF(AND(E33,D33="Pályázatból szerzi be"),AD33-AJ33,"Nem releváns") -> Nem releváns
D34: Nem releváns | E34: =OR(IF(D34="Már rendelkezik vele",1,0),IF(D34="Pályázatból szerzi be",1,0),) -> FALSE | F34: Bevezetés, testre szabás, felhasználói oktatás szolgáltatás | I34: egyszeri költség | J34: 1994300 | K34: 2532761 | M34: nem releváns | S34: sw | T34: =IF(D34="Pályázatból szerzi be",J34,"") | V34: =IF(D34="Pályázatból szerzi be",K34,"") | AA34: Nem releváns, nincs fenntartási kötelezettség | AF34: Nem releváns, nincs fenntartási kötelezettség a bevezetésre | AL34: Nem releváns
B35: 16. | C35: Ügyfélkapcsolat-kezelési (CRM) megoldás használata | D35: Pályázatból szerzi be | E35: =OR(IF(D35="Már rendelkezik vele",1,0),IF(D35="Pályázatból szerzi be",1,0),) -> TRUE | F35: CRM szoftverlicenc / előfizetés | G35: NomadCRM, HubSpot | H35: =IF(AND(D35="Nem releváns",D36="Nem releváns"), "Nem választott fejlesztési cél", IF(AND(E35,E36), CONCATENATE('Egyéb költségek'!A7,CHAR(10),"TELJESÜL"), CONCATENATE('Egyéb költségek'!A7,CHAR(10),"NEM TELJESÜL") ) ) -> A fejlesztési célon belül MINDEN összetevő teljesítése KÖTELEZŐ. TELJESÜL | I35: felhasználó/hó | J35: 20700 | K35: 26289 | M35: 1 | O35: =IF(Alapadatok!I37,1,0) -> 0 | P35: =IF(AND(O35=1,E35,E36),"VAN","NINCS") -> NINCS | R35: =IF(AND(E35,E36,P35="NINCS"),1,"Nem adható pont") -> 1 | S35: sw | T35: =IF(D35="Pályázatból szerzi be",J35*Alapadatok!$H$16*M35,"") -> 248400 | V35: =IF($D35="Pályázatból szerzi be",$M35*Alapadatok!$H$16*K35,"") -> 315468 | X35: Szerződés vagy szerződés hiányában visszaigazolt írásos megrendelő. | Y35: A CRM szoftverlicenc / előfizetés esetében validálni szükséges az elszámolni kívánt (teljesült) felhasználó számot és a hónap meglétét, a Bevezetés és testreszabás esetén pedig a CRM rendszer működését (ami a digitális intenzitási szint emelkedésének validálása során megtörténik). | AA35: =IF(AND(E35,D35="Pályázatból szerzi be"),J35,0) -> 20700 | AB35: =AA35*M35 -> 20700 | AC35: =AB35*12 -> 248400 | AD35: =AB35*36 -> 745200 | AG35: 10000 | AH35: =AG35*M35 -> 10000 | AI35: =AH35*12 -> 120000 | AJ35: =AI35*3 -> 360000 | AL35: =IF(AND(E35,D35="Pályázatból szerzi be"),AD35-AJ35,"Nem releváns") -> 385200
D36: Pályázatból szerzi be | E36: =OR(IF(D36="Már rendelkezik vele",1,0),IF(D36="Pályázatból szerzi be",1,0),) -> TRUE | F36: Bevezetés és testre szabás | I36: egyszeri költség | J36: 1329500 | K36: 1688465 | M36: nem releváns | S36: sw | T36: =IF(D36="Pályázatból szerzi be",J36,"") -> 1329500 | V36: =IF(D36="Pályázatból szerzi be",K36,"") -> 1688465 | AA36: Nem releváns, nincs fenntartási kötelezettség a bevezetésre | AF36: Nem releváns, nincs fenntartási kötelezettség a bevezetésre | AL36: Nem releváns
B37: 21. | C37: Automatizált feldolgozásra alkalmas e-számlák küldése | D37: Nem releváns | E37: =OR(IF(D37="Már rendelkezik vele",1,0),IF(D37="Pályázatból szerzi be",1,0),) -> FALSE | F37: Online számlázó szoftver előfizetés | G37: Számlázz.hu, Billingó | H37: A fejlesztési célon belül az összetevő teljesítése KÖTELEZŐ. | I37: hó | J37: 3200 | K37: 4064 | M37: nem releváns | O37: =IF(Alapadatok!I42,1,0) -> 0 | P37: =IF(AND(O37=1,E37),"VAN","NINCS") -> NINCS | R37: =IF(AND(E37,P37="NINCS"),1,"Nem adható pont") -> Nem adható pont | S37: sw | T37: =IF(D37="Pályázatból szerzi be",J37*Alapadatok!$H$16,"") | V37: =IF($D37="Pályázatból szerzi be",Alapadatok!$H$16*K37,"") | X37: Szerződés vagy szerződés hiányában visszaigazolt írásos megrendelő. | Y37: Az Online számlázó szotver előfizetés esetében a felhívásban szereplő szervezetnek validálnia szükséges az elszámolni kívánt (teljesült) hónapok meglétét. | AA37: =IF(AND(E37,D37="Pályázatból szerzi be"),J37,0) -> 0 | AB37: =AA37 -> 0 | AC37: =AB37*12 -> 0 | AD37: =AB37*36 -> 0 | AF37: Billingo! A számlázz.hu agent sokba kerül! | AG37: =IF(AND(E37,D37="Pályázatból szerzi be"),2490,0) -> 0 | AH37: =AG37 -> 0 | AI37: =AH37*12 -> 0 | AJ37: =AI37*3 -> 0 | AL37: =IF(AND(E37,D37="Pályázatból szerzi be"),AD37-AJ37,"Nem releváns") -> Nem releváns
B38: 22. | C38: Webes értékesítés (forgalom több mint 1%-a; webes értékesítés több mint 10%-a egyéni ügyfeleknek történő értékesítésből származik) | D38: Nem releváns | E38: =OR(IF(D38="Már rendelkezik vele",1,0),IF(D38="Pályázatból szerzi be",1,0),) -> FALSE | F38: Bérelhető webshop rendszer | G38: Unas | H38: =IF(AND(D38="Nem releváns",D39="Nem releváns"), "Nem választott fejlesztési cél", IF(AND(E38,E39), CONCATENATE('Egyéb költségek'!A7,CHAR(10),"TELJESÜL"), CONCATENATE('Egyéb költségek'!A7,CHAR(10),"NEM TELJESÜL") ) ) -> Nem választott fejlesztési cél | I38: hó | J38: 19200 | K38: 24384 | M38: nem releváns | O38: =IF(Alapadatok!I43,1,0) -> 0 | P38: =IF(AND(O38=1,E39,E38),"VAN","NINCS") -> NINCS | R38: =IF(AND(E38,E39,P38="NINCS"),1,"Nem adható pont") -> Nem adható pont | S38: sw | T38: =IF(D38="Pályázatból szerzi be",J38*Alapadatok!$H$16,"") | V38: =IF($D38="Pályázatból szerzi be",Alapadatok!$H$16*K38,"") | X38: Szerződés vagy szerződés hiányában visszaigazolt írásos megrendelő, valamint a weboldal elérhetősége (link). | Y38: A Bérelhető webshop rendszer esetében validálni szükséges az elszámolni kívánt hónapok számát. | AB38: =IF(AND(E38,E39,D38="Pályázatból szerzi be"),J38,0) -> 0 | AC38: =AB38*12 -> 0 | AD38: =AB38*36 -> 0 | AH38: =IF(AND(E38,E39,D38="Pályázatból szerzi be"),J38,0) -> 0 | AI38: =AH38*12 -> 0 | AJ38: =AH38*36 -> 0 | AL38: =IF(AND(E38,D38="Pályázatból szerzi be"),AD38-AJ38,"Nem releváns") -> Nem releváns
D39: Nem releváns | E39: =OR(IF(D39="Már rendelkezik vele",1,0),IF(D39="Pályázatból szerzi be",1,0),) -> FALSE | F39: Domain és tárhely | I39: hó | J39: 3000 | K39: 3810 | M39: nem releváns | S39: sw | T39: =IF(D39="Pályázatból szerzi be",J39*Alapadatok!$H$16,"") | V39: =IF($D39="Pályázatból szerzi be",Alapadatok!$H$16*K39,"") | Y39: A Domain regisztráció esetében validálni szükséges az elszámolni kívánt hónapok számát. | AB39: =IF(AND(E38,E39,D39="Pályázatból szerzi be"),J39,0) -> 0 | AC39: =AB39*12 -> 0 | AD39: =AB39*36 -> 0 | AH39: =IF(AND(E38,E39,D39="Pályázatból szerzi be"),J39,0) -> 0 | AI39: =AH39*12 -> 0 | AJ39: =AH39*36 -> 0 | AL39: =IF(AND(E39,D39="Pályázatból szerzi be"),AD39-AJ39,"Nem releváns") -> Nem releváns
C41: * A „3. Távoli hozzáférés a következők valamelyikéhez: e-mail, dokumentumok, üzleti alkalmazás” és a „6. IKT-szakember igénybevétele” fejlesztési célok egy projektben együttesen nem választhatók. | S41: SZOFTVER | V41: =SUMIFS(T7:T39,S7:S39,"sw") -> 5039400
C42: ** Az „5. IKT-képzés biztosítása az alkalmazottaknak” fejlesztési célra tervezhető összeg nem haladhatja meg a projekt európai unió felé elszámolható összköltségének 20%-át | S42: SZOLGÁLTATÁS | V42: =SUMIFS(T7:T39,S7:S39,"szolg") -> 3543400
...

Sheet Rövid_pdf
B1: A Gipsz Jakab Kft. Az Ön számára az alábbi, zöld színnel megjelölt pályázati célokat tudja szállítani Kontakt: Gipsz Jakab, email: gipsz.jakab@gipszjakabkft.hu; mobil: +36 20 123 4567
B3: Szállítható | C3: Fejlesztési cél | D3: A fejlesztési cél összetevői | E3: Mértékegység | F3: Egységköltség nettó (Ft) | G3: Egységköltség bruttó (Ft)
B4: Igen | C4: Távoli hozzáférés a következők valamelyikéhez: e-mail, dokumentumok, üzleti alkalmazás | D4: SaaS irodai csomag | E4: felhasználó/hó | F4: 5900 | G4: 7493
D5: Domain regisztráció | E5: hó | F5: 200 | G5: 254
D6: Havidíjas IT-üzemeltetés (alapszint) | E6: hó | F6: 127300 | G6: 161671
B7: Igen | C7: Online (távoli) megbeszélések tartása | D7: Videókonferencia platform | E7: felhasználó/hó | F7: 5300 | G7: 6731
D8: Bevezetési, üzemeltetési szolgáltatás | E8: hó | F8: 53000 | G8: 67310
C9: IKT-képzés biztosítása az alkalmazottaknak | D9: IKT-alapképzés** | E9: fő | F9: 96800 | G9: 122936
D10: Haladó digitális készségfejlesztés** | E10: fő | F10: 139100 | G10: 176657
C11: IKT-szakember igénybevétele | D11: IKT-szakember igénybevétele | E11: óra | F11: 9500 | G11: 12065
C12: Alkalmazottak tájékoztatása az IKT-biztonsággal kapcsolatos kötelezettségeikről | D12: IKT-biztonsági képzés*** | E12: fő | F12: 224700 | G12: 285369
C13: Legalább 3 IKT-biztonsági intézkedés alkalmazása | D13: Végpontvédelmi licenc | E13: db/hó | F13: 1400 | G13: 1778
D14: Biztonsági mentés | E14: db/hó | F14: 3000 | G14: 3810
C15: IKT-biztonsági gyakorlatokat, eljárásokat rögzítő dokumentumok megléte | D15: IBSZ (Informatikai Biztonsági Szabályzat) kidolgozása | E15: egyszeri költség | F15: 524300 | G15: 665861
D16: GDPR alapfelmérés és adatkezelési nyilvántartás | E16: egyszeri költség | F16: 257900 | G16: 327533
D17: Incidenskezelési terv és oktatás | E17: fő | F17: 294300 | G17: 373761
D18: Digitális aláírás szolgáltatás | E18: felhasználó/hó | F18: 5200 | G18: 6604
C19: Saját weboldallal/honlappal való rendelkezés | D19: Saját weboldal kialakítása | E19: egyszeri költség | F19: 345100 | G19: 438277
D20: Karbantartás/frissítés | E20: hó | F20: 10100 | G20: 12827
D21: Webtárhely | E21: hó | F21: 1900 | G21: 2413
D22: SSL tanúsítvány | E22: hó | F22: 600 | G22: 762
C23: Bármilyen közösségi média használata | D23: Tartalomgyártás | E23: hó | F23: 74900 | G23: 95123
C24: Kettő vagy több típusú közösségi média használata | D24: Online jelenlét és hirdetések | E24: hó | F24: 96300 | G24: 122301
D25: Képzés* | E25: fő | F25: 374500 | G25: 475615
C26: Bármilyen fizetős felhőszolgáltatás használata | D26: Virtuális szerver (IaaS) | E26: hó | F26: 21800 | G26: 27686
D27: Adattárolás és mentés (felhő storage) | E27: hó | F27: 109100 | G27: 138557
D28: Bevezetés, testre szabás | E28: egyszeri költség | F28: 1039400 | G28: 1320038
D29: MI szolgáltatás | E29: felhasználó/hó | F29: 14400 | G29: 18288
C30: Vállalati erőforrás-tervezési (ERP) megoldás használata | D30: ERP szoftverlicenc / előfizetés (SaaS modell) | E30: felhasználó/hó | F30: 24800 | G30: 31496
D31: Bevezetés, testre szabás, felhasználói oktatás szolgáltatás | E31: egyszeri költség | F31: 1502400 | G31: 1908048
C32: Ügyfélkapcsolat-kezelési (CRM) megoldás használata | D32: CRM szoftverlicenc / előfizetés | E32: felhasználó/hó | F32: 20700 | G32: 26289
D33: Bevezetés és testre szabás | E33: egyszeri költség | F33: 751200 | G33: 954024
C34: Automatizált feldolgozásra alkalmas e-számlák küldése | D34: Online számlázó szoftver előfizetés | E34: hó | F34: 3200 | G34: 4064
C35: Webes értékesítés (forgalom több mint 1%-a; webes értékesítés több mint 10%-a egyéni ügyfeleknek történő értékesítésből származik) | D35: Bérelhető webshop rendszer | E35: hó | F35: 19200 | G35: 24384
D36: Domain és tárhely | E36: hó | F36: 3000 | G36: 3810
B38: Amennyiben olyan fejlesztési célt szeretne megvalósítani, amelyik nincs zöld színnel megjelölve, kérjük keressen a fenti elérhetőségeinken, szívesen segítünk a megoldásban!

Sheet Egyéb költségek
A1: Nem releváns | D1: Nem releváns
A2: Pályázatból szerzi be | D2: Releváns
A7: A fejlesztési célon belül MINDEN összetevő teljesítése KÖTELEZŐ.

Sheet Hosszú_pdf
B1: A Gipsz Jakab Kft. Az Ön számára az alábbi 3 db, zöld színnel megjelölt pályázati fejlesztési célt (+ hardver csomagot) tudja szállítani: Kontakt: Gipsz Jakab, email: gipsz.jakab@gipszjakabkft.hu; mobil: +36 20 123 4567, web: gipszjakabkft.hu
B3: Szállítható | C3: Fejlesztési cél | D3: A fejlesztési cél összetevői | E3: Mértékegység | F3: Egységköltség nettó (Ft) | G3: Egységköltség bruttó (Ft)
B4: Igen | C4: Távoli hozzáférés a következők valamelyikéhez: e-mail, dokumentumok, üzleti alkalmazás | D4: SaaS irodai csomag | E4: felhasználó/hó | F4: 5900 | G4: 7493
D5: Domain regisztráció | E5: hó | F5: 200 | G5: 254
D6: Havidíjas IT-üzemeltetés (alapszint) | E6: hó | F6: 127300 | G6: 161671
B7: Igen | C7: Online (távoli) megbeszélések tartása | D7: Videókonferencia platform | E7: felhasználó/hó | F7: 5300 | G7: 6731
D8: Bevezetési, üzemeltetési szolgáltatás | E8: hó | F8: 53000 | G8: 67310
C9: IKT-képzés biztosítása az alkalmazottaknak | D9: IKT-alapképzés** | E9: fő | F9: 96800 | G9: 122936
D10: Haladó digitális készségfejlesztés** | E10: fő | F10: 139100 | G10: 176657
B11: Igen | C11: IKT-szakember igénybevétele | D11: IKT-szakember igénybevétele | E11: óra | F11: 9500 | G11: 12065
C12: Alkalmazottak tájékoztatása az IKT-biztonsággal kapcsolatos kötelezettségeikről | D12: IKT-biztonsági képzés*** | E12: fő | F12: 224700 | G12: 285369
C13: Legalább 3 IKT-biztonsági intézkedés alkalmazása | D13: Végpontvédelmi licenc | E13: db/hó | F13: 1400 | G13: 1778
D14: Biztonsági mentés | E14: db/hó | F14: 3000 | G14: 3810
C15: IKT-biztonsági gyakorlatokat, eljárásokat rögzítő dokumentumok megléte | D15: IBSZ (Informatikai Biztonsági Szabályzat) kidolgozása | E15: egyszeri költség | F15: 524300 | G15: 665861
D16: GDPR alapfelmérés és adatkezelési nyilvántartás | E16: egyszeri költség | F16: 257900 | G16: 327533
D17: Incidenskezelési terv és oktatás | E17: fő | F17: 294300 | G17: 373761
D18: Digitális aláírás szolgáltatás | E18: felhasználó/hó | F18: 5200 | G18: 6604
C19: Saját weboldallal/honlappal való rendelkezés | D19: Saját weboldal kialakítása | E19: egyszeri költség | F19: 345100 | G19: 438277
D20: Karbantartás/frissítés | E20: hó | F20: 10100 | G20: 12827
D21: Webtárhely | E21: hó | F21: 1900 | G21: 2413
D22: SSL tanúsítvány | E22: hó | F22: 600 | G22: 762
C23: Bármilyen közösségi média használata | D23: Tartalomgyártás | E23: hó | F23: 74900 | G23: 95123
C24: Kettő vagy több típusú közösségi média használata | D24: Online jelenlét és hirdetések | E24: hó | F24: 96300 | G24: 122301
D25: Képzés* | E25: fő | F25: 374500 | G25: 475615
C26: Bármilyen fizetős felhőszolgáltatás használata | D26: Virtuális szerver (IaaS) | E26: hó | F26: 21800 | G26: 27686
D27: Adattárolás és mentés (felhő storage) | E27: hó | F27: 109100 | G27: 138557
D28: Bevezetés, testre szabás | E28: egyszeri költség | F28: 1039400 | G28: 1320038
D29: MI szolgáltatás | E29: felhasználó/hó | F29: 14400 | G29: 18288
C30: Vállalati erőforrás-tervezési (ERP) megoldás használata | D30: ERP szoftverlicenc / előfizetés (SaaS modell) | E30: felhasználó/hó | F30: 24800 | G30: 31496
D31: Bevezetés, testre szabás, felhasználói oktatás szolgáltatás | E31: egyszeri költség | F31: 1502400 | G31: 1908048
C32: Ügyfélkapcsolat-kezelési (CRM) megoldás használata | D32: CRM szoftverlicenc / előfizetés | E32: felhasználó/hó | F32: 20700 | G32: 26289
D33: Bevezetés és testre szabás | E33: egyszeri költség | F33: 751200 | G33: 954024
C34: Automatizált feldolgozásra alkalmas e-számlák küldése | D34: Online számlázó szoftver előfizetés | E34: hó | F34: 3200 | G34: 4064
C35: Webes értékesítés (forgalom több mint 1%-a; webes értékesítés több mint 10%-a egyéni ügyfeleknek történő értékesítésből származik) | D35: Bérelhető webshop rendszer | E35: hó | F35: 19200 | G35: 24384
D36: Domain és tárhely | E36: hó | F36: 3000 | G36: 3810
B38: Amennyiben olyan fejlesztési célt szeretne megvalósítani, amelyik nincs zöld színnel megjelölve, kérjük keressen a fenti elérhetőségeinken, szívesen segítünk a megoldásban!
B42: Részletezés
B43: Fejlesztési cél összetevői | D43: Választható technológia
B44: SaaS irodai csomag | D44: M365 Vállalati alapverzió (Business Basic)
B45: Videókonferencia platform | D45: Cisco WEBEX, MS Teams
...

Sheet Költségvetés
B2: A tervezett beszerzések, projektméret, nettóban: | K2: Arány:
B4: Hardver beszerzések, összesen: | F4: =Hardver!G13 -> 1729800 | G4: =F4/F14 -> 0.1512698 | K4: =CONCATENATE("Projekt összköltségének ",TEXT((F4/F14)*100,"0,00")," %-a") -> Projekt összköltségének 15,13 %-a
B6: Szoftver beszerzések, összesen: | F6: =Szoftver!V41 -> 5039400 | K6: =F6+F8+F10 -> 8957300
B8: Képzés összesen: | F8: =Szoftver!V43 -> 374500
B10: Szolgáltatások, összesen: | F10: =Szoftver!V42 -> 3543400
B12: Egyéb költségek, összesen: | F12: =(F4+F6+F8+F10)*7% -> 748097
B14: Projektköltség mindösszesen: | F14: =((F4+F6+F8+F10)*93%)+F12+F12 -> 11435197 | K14: Az egységköltségek 90%-a kerül kifizetésre
B16: Ebből 10% önerő mértéke, összesen: | F16: =F14*10% -> 1143519.7 | K16: =IF(F18>12000000,CONCATENATE("+ további ",TEXT(ROUND(F18-12000000,0),"### ### ###")," Ft önerő szükséges"),"Nem szükséges a 10%-ot meghaladó önerő vállalása") -> Nem szükséges a 10%-ot meghaladó önerő vállalása
B18: Támogatás, összesen: | F18: =F14-F16 -> 10291677 | G18: =F18/12000000 -> 0.85763978 | K18: =IF(F18>12000000,"Meghaladja a támogatás mértéke a 12MFt-ot",CONCATENATE(TEXT((G18)*100,"0,00")," %")) -> 85,76 %
B21: A pályázat benyújtásánál kapható pontok: | O21: Elvárások | R21: Digitális intenzitási szint | U21: Pontszám | X21: =IF($K$37="Nagyon magas intenzitás",3,IF($K$37="Magas intenzitás",2,IF(K37="Alacsony intenzitás",1,IF(K37="Nagyon alacsony",0,"")))) -> 1
O23: Belépési feltétel: Nagyon alacsony intenzitás | R23: Nagyon alacsony intenzitás | U23: 0 | W23: 5 | X23: 0
B25: Releváns értékelési szempontok | O25: Támogatási cél: Legalább alapszintű intenzitás | R25: Alacsony intenzitás | U25: 6 | W25: 11 | X25: 1
B26: Kibervédelmi intézkedések bevezetése | H26: =Szoftver!R16*2 -> #VALUE! | K26: Adható a +2 pont, ha vállalja a 4 részcél bármelyikét | R26: Magas intenzitás | U26: 12 | W26: 17 | X26: 2
B27: MI alkalmazása | H27: =Szoftver!R32*2 -> 2 | K27: Adható a +2 pont, ha vállalja a fejlesztést | R27: Nagyon magas intenzitás | U27: 18 | W27: 23 | X27: 3
B28: Vállalja, hogy nagyon alacsonyból legalább alacsony szintre növekszik a DII indexe? (+1 szint) | H28: =IF(X21=1,2,"") -> 2 | K28: Adható a +2 pont, ha a vállalás alátámasztható a megadott fejlesztési célokból szerzett pontokkal, illetve az elmozdulás mértékével | O28: =CONCATENATE("Egyéb ellenőrzések:",CHAR(10),B44,CHAR(10),B45) -> Egyéb ellenőrzések: Alkalmazotti IKT képzés elszámolt összege rendben IKT biztonsági képzés elszámolt összege rendben
B29: Vállalja, hogy nagyon alacsonyból legalább magas szintre növekszik a DII indexe? (+2 szint) | H29: =IF(X21>1,4,"") | K29: Adható a +4 pont, ha a vállalás alátámasztható a megadott fejlesztési célokból szerzett pontokkal, illetve az elmozdulás mértékével
B30: Területi dimenzióért adható + pont | H30: 2 | K30: A fejlesztés az Észak-Alföldi- vagy az Észak-Magyarországi- vagy a Dél-Dunántúli- vagy a Dél-Alföldi régió területén történik ?
B31: Vállalja a DFK elkészítését? | H31: =IF(OR(Alapadatok!I10,Alapadatok!I12),2,0) -> 2 | K31: =IF(Alapadatok!I10,"Adható a +2 pont, mert már van DFK",IF(Alapadatok!I12,"Adható a +2 pont, mert vállalja a DFK elkészítését",IF(F18>6000000,"A projektméret miatt kötelező a DFK megszerzése!","Nem választotta, nem kötelező, de beszéljük rá"))) -> Adható a +2 pont, mert vállalja a DFK elkészítését
B32: Összesen: | H32: =SUM(H26:H31) -> #VALUE! | K32: Összesen az alapparaméterek és a vállalások max 12 pontot érnek
B34: Bemeneti DII pont és szint: | H34: =Alapadatok!H46 -> 2 | K34: =IF(H34<=5,"Nagyon alacsony intenzitás, pályázhat", IF(H34<=11,"Alacsony intenzitás, nem pályázhat", IF(H34<=17,"Magas intenzitás, nem pályázhat", IF(H34<=23,"Nagyon magas, nem pályázhat","") ) ) ) -> Nagyon alacsony intenzitás, pályázhat
B37: =CONCATENATE("Kimeneti DII pont (",Alapadatok!H46, "+",Szoftver!R4,") és szint:") -> Kimeneti DII pont (2+5) és szint: | H37: =Alapadatok!H46+Szoftver!R4 -> 7 | K37: =IF(H37<=5,"Nagyon alacsony intenzitás", IF(H37<=11,"Alacsony intenzitás", IF(H37<=17,"Magas intenzitás", IF(H37<=23,"Nagyon magas intenzitás","") ) ) ) -> Alacsony intenzitás
B39: =H37 -> 7
B41: A szintugrás mértéke a fejlesztéseket követően: | H41: =X21 -> 1 | K41: =CONCATENATE("A fejlesztések bevezetésével a pályázó ",IF($K$37="Nagyon magas intenzitás",3,IF($K$37="Magas intenzitás",2,IF(K37="Alacsony intenzitás",1,IF(K37="Nagyon alacsony",0,""))))," szintet ugrik") -> A fejlesztések bevezetésével a pályázó 1 szintet ugrik
B44: =IF((Szoftver!T12+Szoftver!T13)>Költségvetés!F18*20%,"A képzés összeges túl magas, meghaladja a támogatás 20%-át","Alkalmazotti IKT képzés elszámolt összege rendben") -> Alkalmazotti IKT képzés elszámolt összege rendben
B45: =IF(Szoftver!T15>Költségvetés!F18*10%,"A képzés összeges túl magas, meghaladja a támogatás 10%-át","IKT biztonsági képzés elszámolt összege rendben") -> IKT biztonsági képzés elszámolt összege rendben

Sheet Kérdések
A1: Hardver | B1: Szoftver | C1: Szolgáltatás | E1: Eredmény | G1: Milyen változások vannak? A bemutatott logika maradhat? Van már EPTK? Hozzáférést kérhetek? Szeretnék szinkront, és gyors kitöltést előkészíteni) | R1: árkalk nincs, a szállítótól kérjen árat
A2: I | B2: x | C2: x | E2: NEM
A3: x | B3: I | C3: x | E3: NEM | G3: bármilyen és bármennyi HW, ÉS bármilyen és bármennyi SW esetén IGEN, de legalább 1-1 minden kategóriában?
A4: I | B4: I | C4: Csak ilyen esetben | E4: IGEN | G4: Ha csak HW vagy csak SW marad egy szállító kínálatában, mert pl. töröl a meglévő ajánlatai közül, akkor automatikusan inaktiválódik a termék, és tájékoztató üzenetet kap a szállító.Maradhat így?
G5: Kizárólag hardvert szállító töltsön fel legalább 1db szoftvert, csak így engedje az ajánlatot beküldeni!
G6: Mi a helyzet a TelCo cégek termékeivel (Telekom, NaZi) - nincs minden fejlesztési célra megoldásuk !!! Nazi - van több alvállalkozójuk, Telekom: nincs mindenre
G7: Szolgáltatást, oktatást mikor, kinek engedjük meg? Mi ennek a belépési feltétele? Van szállító, aki csak erre specializálódott - mit követelünk meg tőle (1 hw vagy 1 sw elegendő?)
G9: Amit csak csokorba kötve lehet megvenni, azt az ajánlat kiválasztásánál kell kötelezővé tenni (ilyenkor több szállítótól is kell tudnia választani?
G11: Ügyfél ajánlat listázáshoz egy opció javaslat: csak a MINDEN igényre ajánlatot adó szállítók listázása (nem alapértelmezett)
G12: De lehet több szállító is ajánlatadó, ilyenkor minden szállítónak kimegy az érdeklődés, kinek-kinek miről (amit az ügyfél bejelöl) - jó így?
G13: Ilyenkor lehet olyat, hogy a hardvert az A szállítótól, minden mást a B szállítótól vegyen?
G15: Apple 10.89" tablet - nem 11 " a tablet mérete, hanem 10,9" az Apple szerint a kerekített sarok miatt, a felhívás mellékletben (vagy IH állásfoglalással, a felületünkön kiírva) pontosítani szükséges a minimum méretet! Egyébként kizárja a melléklet!
G16: Számítógép és notebook esetében a vasat oprendszerrel együtt kell számlázni és így lehet a max költségre elszámolni, vagy oprendszer nélkül?
G17: Ha valakinek nincs még céges internete a telephelyén, mindenképpen be kell szereznie a 7%-os keret terhére? A mobil internetet is? (+2 pont fontos lenne)
G20: Szállítói tájékoztatás
G21: Akkreditációs kézikönyv szinten (módosítani szükséges !!!)
... G28: Dr. Felhős - Csaba kezeli, mindent megírtam, türelmet kérő email ment

Sheet Alternatív termékek
A1: Aktuális (MNB) EUR középárfolyam: | C1: ='Napi árfolyamok'!D3 -> 379.21
A2: Fejlesztési célok, követelmények alternatív megvalósítási lehetőségei, szakmai tartalom minőségromlása nélkül
A4: Alternatíva: | B4: Havidíja, nettó: | C4: Euro-ban | D4: Megjegyzés
A5: Exchange Plan 1 | B5: =C5*$C$1 -> 1729.1976 | C5: 4.56 | D5: Microsoft 365 Vállalati alapverzió EGT (Teams nélkül)
A6: M365 Business Basic | B6: =C6*$C$1 -> 3640.416 | C6: 9.6 | D6: Microsoft 365 Vállalati standard verzió EGT (Teams nélkül)
A7: M365 Business Standard | B7: =C7*$C$1 -> 7417.3476 | C7: 19.56 | D7: Microsoft 365 Vállalati prémium verzió EGT (Teams nélkül)
A8: Cpanel
A9: NextCloud
A10: VPN
A21: MS Teams | B21: =C21*$C$1 -> 3299.127 | C21: 8.7 | D21: Standard MS Teams telefon
